log/output_50_2020_Attention_gpu3.log
wandb: Currently logged in as: pqy000 (pqythu). Use `wandb login --relogin` to force relogin
GPU device ID: 3
newdata/50_2020.npy
0
2024-09-07 12:04:45.833235: I tensorflow/core/platform/cpu_feature_guard.cc:193] This TensorFlow binary is optimized with oneAPI Deep Neural Network Library (oneDNN) to use the following CPU instructions in performance-critical operations:  AVX2 FMA
To enable them in other operations, rebuild TensorFlow with the appropriate compiler flags.
2024-09-07 12:04:47.130447: W tensorflow/compiler/xla/stream_executor/platform/default/dso_loader.cc:64] Could not load dynamic library 'libnvinfer.so.7'; dlerror: libnvinfer.so.7: cannot open shared object file: No such file or directory; LD_LIBRARY_PATH: /opt/cudnn/lib64:/usr/local/cuda/lib64
2024-09-07 12:04:47.130543: W tensorflow/compiler/xla/stream_executor/platform/default/dso_loader.cc:64] Could not load dynamic library 'libnvinfer_plugin.so.7'; dlerror: libnvinfer_plugin.so.7: cannot open shared object file: No such file or directory; LD_LIBRARY_PATH: /opt/cudnn/lib64:/usr/local/cuda/lib64
2024-09-07 12:04:47.130556: W tensorflow/compiler/tf2tensorrt/utils/py_utils.cc:38] TF-TRT Warning: Cannot dlopen some TensorRT libraries. If you would like to use Nvidia GPU with TensorRT, please make sure the missing libraries mentioned above are installed properly.
wandb: wandb version 0.17.9 is available!  To upgrade, please run:
wandb:  $ pip install wandb --upgrade
wandb: Tracking run with wandb version 0.12.17
wandb: Run data is saved locally in /home/qingyi/GPU20/DeepLOB/wandb/run-20240907_120440-30rn9noi
wandb: Run `wandb offline` to turn off syncing.
wandb: Syncing run Attention
wandb: ⭐️ View project at https://wandb.ai/pqythu/futures50
wandb: 🚀 View run at https://wandb.ai/pqythu/futures50/runs/30rn9noi
Model(
  (attn): MultiheadAttention(
    (out_proj): NonDynamicallyQuantizableLinear(in_features=10, out_features=10, bias=True)
  )
  (fc): Linear(in_features=10, out_features=5, bias=True)
)
number of parameters: 495
Training start
epoch  1 | time used:  0.94s | train_loss 1.493 | valid loss 1.542 | valid acc 0.255 | mae 2.085 | mse 6.750 | rmse 2.60 | r2 -1.81 | sharp 1.74
epoch  2 | time used:  0.08s | train_loss 1.494 | valid loss 1.542 | valid acc 0.255 | mae 2.085 | mse 6.750 | rmse 2.60 | r2 -1.81 | sharp 1.74
epoch  3 | time used:  0.08s | train_loss 1.463 | valid loss 1.522 | valid acc 0.295 | mae 1.915 | mse 6.070 | rmse 2.46 | r2 -1.53 | sharp 0.00
epoch  4 | time used:  0.08s | train_loss 1.428 | valid loss 1.522 | valid acc 0.295 | mae 1.915 | mse 6.070 | rmse 2.46 | r2 -1.53 | sharp 0.00
epoch  5 | time used:  0.08s | train_loss 1.429 | valid loss 1.522 | valid acc 0.295 | mae 1.915 | mse 6.070 | rmse 2.46 | r2 -1.53 | sharp 0.00
epoch  6 | time used:  0.09s | train_loss 1.429 | valid loss 1.522 | valid acc 0.295 | mae 1.915 | mse 6.070 | rmse 2.46 | r2 -1.53 | sharp 0.00
epoch  7 | time used:  0.08s | train_loss 1.429 | valid loss 1.522 | valid acc 0.295 | mae 1.915 | mse 6.070 | rmse 2.46 | r2 -1.53 | sharp 0.00
epoch  8 | time used:  0.20s | train_loss 1.431 | valid loss 1.522 | valid acc 0.295 | mae 1.915 | mse 6.070 | rmse 2.46 | r2 -1.53 | sharp 0.00
epoch  9 | time used:  0.10s | train_loss 1.426 | valid loss 1.522 | valid acc 0.295 | mae 1.915 | mse 6.070 | rmse 2.46 | r2 -1.53 | sharp 0.00
epoch 10 | time used:  0.08s | train_loss 1.433 | valid loss 1.522 | valid acc 0.295 | mae 1.915 | mse 6.070 | rmse 2.46 | r2 -1.53 | sharp 0.00
saving the model to ./save/2020_50/Attention/checkpoint10.pt
epoch 11 | time used:  0.08s | train_loss 1.427 | valid loss 1.522 | valid acc 0.295 | mae 1.915 | mse 6.070 | rmse 2.46 | r2 -1.53 | sharp 0.00
epoch 12 | time used:  0.08s | train_loss 1.428 | valid loss 1.521 | valid acc 0.295 | mae 1.915 | mse 6.070 | rmse 2.46 | r2 -1.53 | sharp 0.00
epoch 13 | time used:  0.08s | train_loss 1.429 | valid loss 1.519 | valid acc 0.295 | mae 1.915 | mse 6.070 | rmse 2.46 | r2 -1.53 | sharp 0.00
epoch 14 | time used:  0.08s | train_loss 1.468 | valid loss 1.542 | valid acc 0.255 | mae 2.085 | mse 6.750 | rmse 2.60 | r2 -1.81 | sharp 1.74
epoch 15 | time used:  0.08s | train_loss 1.493 | valid loss 1.542 | valid acc 0.255 | mae 2.085 | mse 6.750 | rmse 2.60 | r2 -1.81 | sharp 1.74
epoch 16 | time used:  0.08s | train_loss 1.497 | valid loss 1.542 | valid acc 0.255 | mae 2.085 | mse 6.750 | rmse 2.60 | r2 -1.81 | sharp 1.74
epoch 17 | time used:  0.08s | train_loss 1.494 | valid loss 1.522 | valid acc 0.295 | mae 1.915 | mse 6.070 | rmse 2.46 | r2 -1.53 | sharp 0.00
epoch 18 | time used:  0.08s | train_loss 1.428 | valid loss 1.522 | valid acc 0.295 | mae 1.915 | mse 6.070 | rmse 2.46 | r2 -1.53 | sharp 0.00
epoch 19 | time used:  0.08s | train_loss 1.454 | valid loss 1.542 | valid acc 0.255 | mae 2.085 | mse 6.750 | rmse 2.60 | r2 -1.81 | sharp 1.74
epoch 20 | time used:  0.08s | train_loss 1.496 | valid loss 1.542 | valid acc 0.255 | mae 2.085 | mse 6.750 | rmse 2.60 | r2 -1.81 | sharp 1.74
saving the model to ./save/2020_50/Attention/checkpoint20.pt
epoch 21 | time used:  0.08s | train_loss 1.493 | valid loss 1.542 | valid acc 0.255 | mae 2.085 | mse 6.750 | rmse 2.60 | r2 -1.81 | sharp 1.74
epoch 22 | time used:  0.08s | train_loss 1.497 | valid loss 1.542 | valid acc 0.255 | mae 2.085 | mse 6.750 | rmse 2.60 | r2 -1.81 | sharp 1.74
epoch 23 | time used:  0.07s | train_loss 1.495 | valid loss 1.542 | valid acc 0.255 | mae 2.085 | mse 6.750 | rmse 2.60 | r2 -1.81 | sharp 1.74
epoch 24 | time used:  0.08s | train_loss 1.495 | valid loss 1.542 | valid acc 0.255 | mae 2.085 | mse 6.750 | rmse 2.60 | r2 -1.81 | sharp 1.74
epoch 25 | time used:  0.08s | train_loss 1.496 | valid loss 1.542 | valid acc 0.255 | mae 2.085 | mse 6.750 | rmse 2.60 | r2 -1.81 | sharp 1.74
epoch 26 | time used:  0.08s | train_loss 1.493 | valid loss 1.542 | valid acc 0.255 | mae 2.085 | mse 6.750 | rmse 2.60 | r2 -1.81 | sharp 1.74
epoch 27 | time used:  0.08s | train_loss 1.496 | valid loss 1.542 | valid acc 0.255 | mae 2.085 | mse 6.750 | rmse 2.60 | r2 -1.81 | sharp 1.74
epoch 28 | time used:  0.07s | train_loss 1.497 | valid loss 1.542 | valid acc 0.255 | mae 2.085 | mse 6.750 | rmse 2.60 | r2 -1.81 | sharp 1.74
epoch 29 | time used:  0.07s | train_loss 1.495 | valid loss 1.542 | valid acc 0.255 | mae 2.085 | mse 6.750 | rmse 2.60 | r2 -1.81 | sharp 1.74
epoch 30 | time used:  0.07s | train_loss 1.500 | valid loss 1.542 | valid acc 0.255 | mae 2.085 | mse 6.750 | rmse 2.60 | r2 -1.81 | sharp 1.74
saving the model to ./save/2020_50/Attention/checkpoint30.pt
epoch 31 | time used:  0.07s | train_loss 1.496 | valid loss 1.542 | valid acc 0.255 | mae 2.085 | mse 6.750 | rmse 2.60 | r2 -1.81 | sharp 1.74
epoch 32 | time used:  0.07s | train_loss 1.494 | valid loss 1.542 | valid acc 0.255 | mae 2.085 | mse 6.750 | rmse 2.60 | r2 -1.81 | sharp 1.74
epoch 33 | time used:  0.07s | train_loss 1.493 | valid loss 1.542 | valid acc 0.255 | mae 2.085 | mse 6.750 | rmse 2.60 | r2 -1.81 | sharp 1.74
epoch 34 | time used:  0.07s | train_loss 1.494 | valid loss 1.542 | valid acc 0.255 | mae 2.085 | mse 6.750 | rmse 2.60 | r2 -1.81 | sharp 1.74
epoch 35 | time used:  0.08s | train_loss 1.495 | valid loss 1.542 | valid acc 0.255 | mae 2.085 | mse 6.750 | rmse 2.60 | r2 -1.81 | sharp 1.74
epoch 36 | time used:  0.09s | train_loss 1.498 | valid loss 1.542 | valid acc 0.255 | mae 2.085 | mse 6.750 | rmse 2.60 | r2 -1.81 | sharp 1.74
epoch 37 | time used:  0.13s | train_loss 1.491 | valid loss 1.542 | valid acc 0.255 | mae 2.085 | mse 6.750 | rmse 2.60 | r2 -1.81 | sharp 1.74
epoch 38 | time used:  0.14s | train_loss 1.471 | valid loss 1.519 | valid acc 0.295 | mae 1.915 | mse 6.070 | rmse 2.46 | r2 -1.53 | sharp 0.00
epoch 39 | time used:  0.19s | train_loss 1.426 | valid loss 1.522 | valid acc 0.295 | mae 1.915 | mse 6.070 | rmse 2.46 | r2 -1.53 | sharp 0.00
epoch 40 | time used:  0.07s | train_loss 1.428 | valid loss 1.522 | valid acc 0.295 | mae 1.915 | mse 6.070 | rmse 2.46 | r2 -1.53 | sharp 0.00
